Workbook
Name Data: OFFSET(Data!$A$1,0,0,COUNTA(Data!$A:$A),COUNTA(Data!$A$1:$BJ$1))

Sheet TOP User Error VS Account
B2: Account Name
A3: MT Name | B3: CAMG | C3: HCA | D3: NCSB | E3: AMC | F3: SOC | G3: CCM | H3: DHS | I3: ICA | J3: HMRH | K3: CVAMD | L3: WOS | M3: NLC | N3: LAC | O3: RMCA | P3: Grand Total
A4: Purvi Thakore | B4: 11 | K4: 3 | M4: 1 | P4: 15
A5: Prasanth Sivan | E5: 4 | F5: 5 | N5: 1 | P5: 10
A6: Pratheep Kumar | B6: 5 | H6: 2 | L6: 2 | O6: 1 | P6: 10
A7: Aarti Gajjar | B7: 2 | C7: 7 | G7: 1 | P7: 10
A8: Febin Clament | I8: 6 | J8: 1 | N8: 2 | P8: 9
A9: Sivasankari A | D9: 8 | P9: 8
A11: MT Name | B11: HCA | C11: PRMC | D11: OHH | E11: AMC | F11: DHS | G11: CAMG | H11: SOC | I11: NCSB | J11: CPRC | K11: NLC | L11: MJHS | M11: SHWS | N11: Grand Total
A12: Vijay Babu | B12: 3 | C12: 1 | D12: 2 | L12: 1 | M12: 1 | N12: 8
A13: Santosh Singh | B13: 5 | F13: 1 | G13: 1 | N13: 7
A14: Savitha Arun | C14: 2 | H14: 1 | I14: 2 | J14: 1 | N14: 6
A15: Chintul Sutaria | E15: 2 | F15: 1 | K15: 1 | N15: 4

Sheet Auditors Status
A2: Responsible_User_Status | B2: (All) | G2: Auditor_milestone | H2: cqa | M2: Auditor_milestone | N2: (All)
A3: T/F | B3: FALSE | G3: T/F | H3: FALSE | M3: T/F | N3: FALSE
A5: Auditor Name | B5: Average of Accuracy | C5: Count of Error | D5: Occurrences of Error | E5: Count of File | G5: Account Name | H5: Count of Error | I5: Occurrences of Error | J5: Count of File | M5: Auditor Milestone / Auditor Name | N5: Count of File_name
A6: cqa | B6: 98.766605 | C6: 158 | D6: 408 | E6: 240 | G6: DHS | H6: 20 | I6: 75 | J6: 23 | M6: Devang Thakkar | N6: 239
A7: Devang Thakkar | B7: 98.761444 | C7: 158 | D7: 408 | E7: 239 | G7: AMC | H7: 17 | I7: 35 | J7: 25 | M7: Vishal Mehta | N7: 1
A8: Vishal Mehta | B8: 100 | C8: 0 | D8: 0 | E8: 1 | G8: RMCA | H8: 5 | I8: 8 | J8: 15 | M8: Grand Total | N8: 240
A9: Grand Total | B9: 98.766605 | C9: 158 | D9: 408 | E9: 240 | G9: CAMG | H9: 44 | I9: 120 | J9: 51
G10: PRMC | H10: 11 | I10: 18 | J10: 16
G11: Auburn HIM | H11: 3 | I11: 10 | J11: 4
G12: SMH | H12: 2 | I12: 2 | J12: 5
G13: LAC | H13: 5 | I13: 7 | J13: 8
G14: HMRH | H14: 7 | I14: 13 | J14: 12
G15: NCSB | H15: 10 | I15: 23 | J15: 25
G16: MJHS | H16: 4 | I16: 5 | J16: 5
G17: FVLD | H17: 6 | I17: 16 | J17: 6
G18: CRNRC | H18: 2 | I18: 11 | J18: 2
G19: HHRC | H19: 1 | I19: 4 | J19: 1
G20: SSH | H20: 2 | I20: 6 | J20: 4
G21: MRC | H21: 3 | I21: 15 | J21: 3
... G31: Grand Total | H31: 158 | I31: 408 | J31: 240

Sheet Status Wise Quality
B1: Awaiting BB | H1: Awaiting Upload | N1: Awaiting QA | T1: Ready_for_review | Z1: Decision_Pending
B2: Sent Status Name | C2: awaiting_upload | H2: Sent Status Name | I2: awaiting_upload | N2: Sent Status Name | O2: awaiting_upload | T2: Sent Status Name | U2: awaiting_upload | Z2: Sent Status Name | AA2: awaiting_upload
B3: T/F | C3: FALSE | H3: T/F | I3: FALSE | N3: T/F | O3: FALSE | T3: T/F | U3: FALSE | Z3: T/F | AA3: FALSE
B5: Responsible_User_Status | C5: Responsible_User_Name | D5: Average of Accuracy | E5: Error Count | F5: Error Occurrences | H5: Responsible_User_Status | I5: Responsible_User_Name | J5: Average of Accuracy | K5: Error Count | L5: Error Occurrences | N5: Responsible_User_Status | O5: Responsible_User_Name | P5: Average of Accuracy | Q5: Error Count | R5: Error Occurrences | T5: Responsible_User_Status | U5: Responsible_User_Name | V5: Average of Accuracy | W5: Error Count | X5: Error Occurrences | Z5: Responsible_User_Status | AA5: Responsible_User_Name | AB5: Error Count | AC5: Error Occurrences
B6: mt_new | D6: 98.86003 | E6: 121 | F6: 276 | H6: mt_new | J6: 98.86003 | K6: 121 | L6: 276 | N6: qa_new | P6: 98.622307 | Q6: 25 | R6: 77 | T6: qa_new | V6: 98.622307 | W6: 25 | X6: 77 | Z6: qa_new | AB6: 25 | AC6: 77
C7: Vijay Babu | D7: 99.655621 | E7: 11 | F7: 22 | I7: Vijay Babu | J7: 99.655621 | K7: 11 | L7: 22 | O7: Vijay Babu | P7: 99.661247 | Q7: 1 | R7: 1 | U7: Vijay Babu | V7: 99.661247 | W7: 1 | X7: 1 | AA7: Vijay Babu | AB7: 1 | AC7: 1
C8: Pratheep Kumar | D8: 99.107497 | E8: 17 | F8: 37 | I8: Pratheep Kumar | J8: 99.107497 | K8: 17 | L8: 37 | O8: Savitha Arun | P8: 98.301198 | Q8: 11 | R8: 34 | U8: Savitha Arun | V8: 98.301198 | W8: 11 | X8: 34 | AA8: Savitha Arun | AB8: 11 | AC8: 34
C9: Shiny Iype | D9: 95.162649 | E9: 22 | F9: 79 | I9: Shiny Iype | J9: 95.162649 | K9: 22 | L9: 79 | O9: Chintul Sutaria | P9: 98.826299 | Q9: 13 | R9: 42 | U9: Chintul Sutaria | V9: 98.826299 | W9: 13 | X9: 42 | AA9: Chintul Sutaria | AB9: 13 | AC9: 42
C10: Savitha Arun | D10: 100 | E10: 0 | F10: 0 | I10: Savitha Arun | J10: 100 | K10: 0 | L10: 0 | N10: mt_new | P10: 98.86003 | Q10: 121 | R10: 276 | T10: mt_new | V10: 98.86003 | W10: 121 | X10: 276 | Z10: mt_new | AB10: 121 | AC10: 276
C11: Gopal Rajith | D11: 99.705796 | E11: 9 | F11: 16 | I11: Gopal Rajith | J11: 99.705796 | K11: 9 | L11: 16 | O11: Vijay Babu | P11: 99.655621 | Q11: 11 | R11: 22 | U11: Vijay Babu | V11: 99.655621 | W11: 11 | X11: 22 | AA11: Vijay Babu | AB11: 11 | AC11: 22
C12: Sandeep S | D12: 99.297783 | E12: 14 | F12: 21 | I12: Sandeep S | J12: 99.297783 | K12: 14 | L12: 21 | O12: Pratheep Kumar | P12: 99.107497 | Q12: 17 | R12: 37 | U12: Pratheep Kumar | V12: 99.107497 | W12: 17 | X12: 37 | AA12: Shiny Iype | AB12: 22 | AC12: 79
C13: Usha M | D13: 98.596779 | E13: 14 | F13: 21 | I13: Usha M | J13: 98.596779 | K13: 14 | L13: 21 | O13: Shiny Iype | P13: 95.162649 | Q13: 22 | R13: 79 | U13: Shiny Iype | V13: 95.162649 | W13: 22 | X13: 79 | AA13: Savitha Arun | AB13: 0 | AC13: 0
C14: Sivasankari A | D14: 99.783624 | E14: 9 | F14: 21 | I14: Sivasankari A | J14: 99.783624 | K14: 9 | L14: 21 | O14: Savitha Arun | P14: 100 | Q14: 0 | R14: 0 | U14: Savitha Arun | V14: 100 | W14: 0 | X14: 0 | AA14: Pratheep Kumar | AB14: 17 | AC14: 37
C15: Chintul Sutaria | D15: 99.350504 | E15: 7 | F15: 17 | I15: Chintul Sutaria | J15: 99.350504 | K15: 7 | L15: 17 | O15: Gopal Rajith | P15: 99.705796 | Q15: 9 | R15: 16 | U15: Gopal Rajith | V15: 99.705796 | W15: 9 | X15: 16 | AA15: Gopal Rajith | AB15: 9 | AC15: 16
C16: Tejas Patel | D16: 99.086854 | E16: 18 | F16: 42 | I16: Tejas Patel | J16: 99.086854 | K16: 18 | L16: 42 | O16: Sandeep S | P16: 99.297783 | Q16: 14 | R16: 21 | U16: Sandeep S | V16: 99.297783 | W16: 14 | X16: 21 | AA16: Sandeep S | AB16: 14 | AC16: 21
B17: qa_new | D17: 98.622307 | E17: 25 | F17: 77 | H17: qa_new | J17: 98.622307 | K17: 25 | L17: 77 | O17: Usha M | P17: 98.596779 | Q17: 14 | R17: 21 | U17: Usha M | V17: 98.596779 | W17: 14 | X17: 21 | AA17: Usha M | AB17: 14 | AC17: 21
C18: Vijay Babu | D18: 99.661247 | E18: 1 | F18: 1 | I18: Vijay Babu | J18: 99.661247 | K18: 1 | L18: 1 | O18: Sivasankari A | P18: 99.783624 | Q18: 9 | R18: 21 | U18: Sivasankari A | V18: 99.783624 | W18: 9 | X18: 21 | AA18: Sivasankari A | AB18: 9 | AC18: 21
C19: Savitha Arun | D19: 98.301198 | E19: 11 | F19: 34 | I19: Savitha Arun | J19: 98.301198 | K19: 11 | L19: 34 | O19: Chintul Sutaria | P19: 99.350504 | Q19: 7 | R19: 17 | U19: Chintul Sutaria | V19: 99.350504 | W19: 7 | X19: 17 | AA19: Chintul Sutaria | AB19: 7 | AC19: 17
C20: Chintul Sutaria | D20: 98.826299 | E20: 13 | F20: 42 | I20: Chintul Sutaria | J20: 98.826299 | K20: 13 | L20: 42 | O20: Tejas Patel | P20: 99.086854 | Q20: 18 | R20: 42 | U20: Tejas Patel | V20: 99.086854 | W20: 18 | X20: 42 | AA20: Tejas Patel | AB20: 18 | AC20: 42
B21: Grand Total | D21: 98.825471 | E21: 146 | F21: 353 | H21: Grand Total | J21: 98.825471 | K21: 146 | L21: 353 | N21: Grand Total | P21: 98.825471 | Q21: 146 | R21: 353 | T21: Grand Total | V21: 98.825471 | W21: 146 | X21: 353 | Z21: Grand Total | AB21: 146 | AC21: 353

Sheet DashBoard
B2: Total Files Audited | E2: GO % | H2: NoGo Count | K2: NoGo %
B3: =GETPIVOTDATA("File_name",'Master Pivot'!$A$4) -> 240 | E3: =GETPIVOTDATA("File_name",'Master Pivot'!$A$4,"NoGo/Go","Go")/DashBoard!B3 -> 0.725 | H3: =GETPIVOTDATA("File_name",'Master Pivot'!$A$4,"NoGo/Go","NoGo") -> 66 | K3: =GETPIVOTDATA("File_name",'Master Pivot'!$A$4,"NoGo/Go","NoGo")/B3 -> 0.275
Z8: Status | AA8: Count
Z9: Go | AA9: =GETPIVOTDATA("File_name",'Master Pivot'!$A$4,"NoGo/Go","Go") -> 174
Z10: NoGo | AA10: =GETPIVOTDATA("File_name",'Master Pivot'!$A$4,"NoGo/Go","NoGo") -> 66

Sheet Master Pivot
A1: T/F | B1: FALSE
A2: Audited Date | B2: (All)
D4: NoGo/Go
A5: Account_name | B5: Doctor | C5: Responsible_User_Name | D5: Go | E5: NoGo | F5: Grand Total
A6: Cardiology Associates Medical Group | B6: Jeffrey C Brackett, MD, FACC | C6: Shiny Iype | D6: 5 | E6: 3 | F6: 8
C7: Pratheep Kumar | D7: 3 | E7: 4 | F7: 7
C8: Tejas Patel | D8: 3 | E8: 2 | F8: 5
B9: Jeffrey C Brackett, MD, FACC Total | D9: 11 | E9: 9 | F9: 20
B10: Melissa Murillo, PA | C10: Shiny Iype | E10: 3 | F10: 3
C11: Tejas Patel | E11: 2 | F11: 2
C12: Pratheep Kumar | D12: 1 | F12: 1
B13: Melissa Murillo, PA Total | D13: 1 | E13: 5 | F13: 6
B14: Brian Martinez, PAC | C14: Pratheep Kumar | D14: 3 | E14: 1 | F14: 4
C15: Shiny Iype | E15: 2 | F15: 2
B16: Brian Martinez, PAC Total | D16: 3 | E16: 3 | F16: 6
B17: Craig Mansour, MD | C17: Shiny Iype | E17: 3 | F17: 3
B18: Craig Mansour, MD Total | E18: 3 | F18: 3
B19: Julie Morantz, PA | C19: Tejas Patel | D19: 7 | E19: 1 | F19: 8
B20: Julie Morantz, PA Total | D20: 7 | E20: 1 | F20: 8
B21: Alon A Steinberg, MD, FACC | C21: Chintul Sutaria | E21: 1 | F21: 1
B22: Alon A Steinberg, MD, FACC Total | E22: 1 | F22: 1
B23: Jonathan Dukes, MD | C23: Chintul Sutaria | E23: 1 | F23: 1
B24: Jonathan Dukes, MD Total | E24: 1 | F24: 1
B25: Robert Sogomonian, MD | C25: Pratheep Kumar | D25: 3 | F25: 3
B26: Robert Sogomonian, MD Total | D26: 3 | F26: 3
B27: Shaun T Patel, MD FACC | C27: Tejas Patel | D27: 2 | F27: 2
C28: Pratheep Kumar | D28: 1 | F28: 1
B29: Shaun T Patel, MD FACC Total | D29: 3 | F29: 3
A30: Cardiology Associates Medical Group Total | D30: 28 | E30: 23 | F30: 51
A31: Peterson Regional Medical Center | B31: Melissa G Wampler, MD | C31: Usha M | E31: 1 | F31: 1
B32: Melissa G Wampler, MD Total | E32: 1 | F32: 1
B33: Sylvester G Ramirez, MD | C33: Savitha Arun | E33: 1 | F33: 1
B34: Sylvester G Ramirez, MD Total | E34: 1 | F34: 1
B35: Paul Valenza, DPM | C35: Usha M | E35: 1 | F35: 1
C36: Sandeep S | D36: 1 | F36: 1
B37: Paul Valenza, DPM Total | D37: 1 | E37: 1 | F37: 2
B38: Kara E Whittington, DDS | C38: Usha M | D38: 1 | F38: 1
C39: Sandeep S | E39: 1 | F39: 1
B40: Kara E Whittington, DDS Total | D40: 1 | E40: 1 | F40: 2
B41: Mark P Goldman, PhD | C41: Vijay Babu | D41: 1 | F41: 1
...

Sheet Top
A1: User Name | B1: Go | C1: NoGo | D1: Grand Total | E1: NoGo%
A2: Shiny Iype | B2: 8 | C2: 17 | D2: 25 | E2: =C2/D2 -> 0.68
A3: Usha M | B3: 15 | C3: 10 | D3: 25 | E3: =C3/D3 -> 0.4
A4: Tejas Patel | B4: 17 | C4: 8 | D4: 25 | E4: =C4/D4 -> 0.32
A5: Savitha Arun | B5: 12 | C5: 8 | D5: 20 | E5: =C5/D5 -> 0.4
A6: Chintul Sutaria | B6: 18 | C6: 7 | D6: 25 | E6: =C6/D6 -> 0.28
A7: Pratheep Kumar | B7: 15 | C7: 6 | D7: 21 | E7: =C7/D7 -> 0.28571429
A8: Sandeep S | B8: 20 | C8: 5 | D8: 25 | E8: =C8/D8 -> 0.2
A9: Vijay Babu | B9: 23 | C9: 2 | D9: 25 | E9: =C9/D9 -> 0.08
A10: Sivasankari A | B10: 23 | C10: 2 | D10: 25 | E10: =C10/D10 -> 0.08
A11: Gopal Rajith | B11: 23 | C11: 1 | D11: 24 | E11: =C11/D11 -> 0.041666667

Sheet MT-Hospital-Doctor
A1: Responsible_User_Name | B1: Responsible_User_Status | C1: Account_name | D1: Doctor | E1: Go | F1: NoGo | G1: Grand Total | H1: NoGo%
A2: Shiny Iype | B2: mt_new | C2: Cardiology Associates Medical Group | D2: Brian Martinez, PAC | F2: 2 | G2: 2 | H2: =F2/G2 -> 1
A3: Shiny Iype | B3: mt_new | C3: Cardiology Associates Medical Group | D3: Craig Mansour, MD | F3: 3 | G3: 3 | H3: =F3/G3 -> 1
A4: Shiny Iype | B4: mt_new | C4: Cardiology Associates Medical Group | D4: Jeffrey C Brackett, MD, FACC | E4: 5 | F4: 3 | G4: 8 | H4: =F4/G4 -> 0.375
A5: Shiny Iype | B5: mt_new | C5: Cardiology Associates Medical Group | D5: Melissa Murillo, PA | F5: 3 | G5: 3 | H5: =F5/G5 -> 1
A6: Shiny Iype | B6: mt_new | C6: Department Of Health Services - Wisconsin | D6: Scott Trippe, Psy.D. | F6: 1 | G6: 1 | H6: =F6/G6 -> 1
A7: Shiny Iype | B7: mt_new | C7: MEDICAL RESOURCE CENTER | D7: Jules J Barefoot, | E7: 1 | G7: 1 | H7: =F7/G7 -> 0
A8: Shiny Iype | B8: mt_new | C8: Fred V Lause, DPM | D8: Fred V Lause, DPM | F8: 4 | G8: 4 | H8: =F8/G8 -> 1
A9: Shiny Iype | B9: mt_new | C9: Auburn Community Hospital | D9: Daniel Alexander, MD | E9: 1 | F9: 1 | G9: 2 | H9: =F9/G9 -> 0.5
A10: Shiny Iype | B10: mt_new | C10: Auburn Community Hospital | D10: Kathi F Teixeira, MD | E10: 1 | G10: 1 | H10: =F10/G10 -> 0
A11: Shiny Iype | B11: mt_new Total | E11: 8 | F11: 17 | G11: 25 | H11: =F11/G11 -> 0.68
A12: Shiny Iype Total | E12: 8 | F12: 17 | G12: 25 | H12: =F12/G12 -> 0.68
A13: Usha M | B13: mt_new | C13: Adirondack Medical Center | D13: Eve Burns, MD | F13: 1 | G13: 1 | H13: =F13/G13 -> 1
B14: mt_new | C14: Adirondack Medical Center | D14: Jeffrey Dodge, DO | E14: 1 | G14: 1 | H14: =F14/G14 -> 0
B15: mt_new | C15: Adirondack Medical Center | D15: John Decker, MD | E15: 1 | G15: 1 | H15: =F15/G15 -> 0
B16: mt_new | C16: Adirondack Medical Center | D16: William Smith, MD | E16: 1 | F16: 1 | G16: 2 | H16: =F16/G16 -> 0.5
B17: mt_new | C17: Harmon Medical And Rehabilitation Hospital | D17: Gnaneswer Billakanti, MD | E17: 1 | G17: 1 | H17: =F17/G17 -> 0
B18: mt_new | C18: Hillsboro Area Hospital | D18: Blake Little, MD | F18: 1 | G18: 1 | H18: =F18/G18 -> 1
B19: mt_new | C19: Hillsboro Area Hospital | D19: Joel Wietfeldt, MD | F19: 1 | G19: 1 | H19: =F19/G19 -> 1
B20: mt_new | C20: Hillsboro Area Hospital | D20: Joseph Blaser, DO | E20: 4 | G20: 4 | H20: =F20/G20 -> 0
B21: mt_new | C21: Peterson Regional Medical Center | D21: Emmett R Mackan, MD | E21: 2 | G21: 2 | H21: =F21/G21 -> 0
B22: mt_new | C22: Peterson Regional Medical Center | D22: Kara E Whittington, DDS | E22: 1 | G22: 1 | H22: =F22/G22 -> 0
B23: mt_new | C23: Peterson Regional Medical Center | D23: Mark P Goldman, PhD | F23: 1 | G23: 1 | H23: =F23/G23 -> 1
B24: mt_new | C24: Peterson Regional Medical Center | D24: Michael E Guerra, MD | E24: 1 | G24: 1 | H24: =F24/G24 -> 0
B25: mt_new | C25: Peterson Regional Medical Center | D25: Paul Valenza, DPM | F25: 1 | G25: 1 | H25: =F25/G25 -> 1
B26: mt_new | C26: Peterson Regional Medical Center | D26: Ralph J Fritzsch, MD | E26: 1 | G26: 1 | H26: =F26/G26 -> 0
B27: mt_new | C27: Peterson Regional Medical Center | D27: Ryan J Veurink, MD | E27: 1 | G27: 1 | H27: =F27/G27 -> 0
B28: mt_new | C28: Peterson Regional Medical Center | D28: Melissa G Wampler, MD | F28: 1 | G28: 1 | H28: =F28/G28 -> 1
B29: mt_new | C29: Stringfellow Memorial Hospital | D29: JEFFREY LAWLER, MD | F29: 2 | G29: 2 | H29: =F29/G29 -> 1
B30: mt_new | C30: Sterling Surgical Hospital | D30: Christopher Sanchez, MD | E30: 1 | G30: 1 | H30: =F30/G30 -> 0
B31: mt_new | C31: Sterling Surgical Hospital | D31: John Chip Davis, MD | F31: 1 | G31: 1 | H31: =F31/G31 -> 1
B32: mt_new Total | E32: 15 | F32: 10 | G32: 25 | H32: =F32/G32 -> 0.4
A33: Usha M Total | E33: 15 | F33: 10 | G33: 25 | H33: =F33/G33 -> 0.4
A34: Tejas Patel | B34: mt_new | C34: Cardiology Associates Medical Group | D34: Jeffrey C Brackett, MD, FACC | E34: 3 | F34: 2 | G34: 5 | H34: =F34/G34 -> 0.4
A35: Tejas Patel | B35: mt_new | C35: Cardiology Associates Medical Group | D35: Julie Morantz, PA | E35: 7 | F35: 1 | G35: 8 | H35: =F35/G35 -> 0.125
A36: Tejas Patel | B36: mt_new | C36: Cardiology Associates Medical Group | D36: Shaun T Patel, MD FACC | E36: 2 | G36: 2 | H36: =F36/G36 -> 0
A37: Tejas Patel | B37: mt_new | C37: Cardiology Associates Medical Group | D37: Melissa Murillo, PA | F37: 2 | G37: 2 | H37: =F37/G37 -> 1
A38: Tejas Patel | B38: mt_new | C38: Department Of Health Services - Wisconsin | D38: Brian Allen, DO | E38: 1 | G38: 1 | H38: =F38/G38 -> 0
A39: Tejas Patel | B39: mt_new | C39: Department Of Health Services - Wisconsin | D39: David Radovich, Psy.D | E39: 2 | G39: 2 | H39: =F39/G39 -> 0
A40: Tejas Patel | B40: mt_new | C40: Department Of Health Services - Wisconsin | D40: Mark Pushkash, Ph.D. | E40: 1 | F40: 2 | G40: 3 | H40: =F40/G40 -> 0.66666667
...

Sheet Doctor
A2: T/F | B2: FALSE
A3: Audited Date | B3: (All)
D5: NoGo/Go
A6: Account_name | B6: Doctor | C6: Responsible_User_Name | D6: Go | E6: NoGo | F6: Grand Total
A7: Cardiology Associates Medical Group | B7: Jeffrey C Brackett, MD, FACC | C7: Shiny Iype | D7: 5 | E7: 3 | F7: 8
C8: Pratheep Kumar | D8: 3 | E8: 4 | F8: 7
C9: Tejas Patel | D9: 3 | E9: 2 | F9: 5
B10: Jeffrey C Brackett, MD, FACC Total | D10: 11 | E10: 9 | F10: 20
B11: Melissa Murillo, PA | C11: Shiny Iype | E11: 3 | F11: 3
C12: Tejas Patel | E12: 2 | F12: 2
C13: Pratheep Kumar | D13: 1 | F13: 1
B14: Melissa Murillo, PA Total | D14: 1 | E14: 5 | F14: 6
B15: Brian Martinez, PAC | C15: Pratheep Kumar | D15: 3 | E15: 1 | F15: 4
C16: Shiny Iype | E16: 2 | F16: 2
B17: Brian Martinez, PAC Total | D17: 3 | E17: 3 | F17: 6
B18: Craig Mansour, MD | C18: Shiny Iype | E18: 3 | F18: 3
B19: Craig Mansour, MD Total | E19: 3 | F19: 3
B20: Julie Morantz, PA | C20: Tejas Patel | D20: 7 | E20: 1 | F20: 8
B21: Julie Morantz, PA Total | D21: 7 | E21: 1 | F21: 8
B22: Alon A Steinberg, MD, FACC | C22: Chintul Sutaria | E22: 1 | F22: 1
B23: Alon A Steinberg, MD, FACC Total | E23: 1 | F23: 1
B24: Jonathan Dukes, MD | C24: Chintul Sutaria | E24: 1 | F24: 1
B25: Jonathan Dukes, MD Total | E25: 1 | F25: 1
B26: Robert Sogomonian, MD | C26: Pratheep Kumar | D26: 3 | F26: 3
B27: Robert Sogomonian, MD Total | D27: 3 | F27: 3
B28: Shaun T Patel, MD FACC | C28: Tejas Patel | D28: 2 | F28: 2
C29: Pratheep Kumar | D29: 1 | F29: 1
B30: Shaun T Patel, MD FACC Total | D30: 3 | F30: 3
A31: Cardiology Associates Medical Group Total | D31: 28 | E31: 23 | F31: 51
A32: Peterson Regional Medical Center | B32: Melissa G Wampler, MD | C32: Usha M | E32: 1 | F32: 1
B33: Melissa G Wampler, MD Total | E33: 1 | F33: 1
B34: Sylvester G Ramirez, MD | C34: Savitha Arun | E34: 1 | F34: 1
B35: Sylvester G Ramirez, MD Total | E35: 1 | F35: 1
B36: Paul Valenza, DPM | C36: Usha M | E36: 1 | F36: 1
C37: Sandeep S | D37: 1 | F37: 1
B38: Paul Valenza, DPM Total | D38: 1 | E38: 1 | F38: 2
B39: Kara E Whittington, DDS | C39: Usha M | D39: 1 | F39: 1
C40: Sandeep S | E40: 1 | F40: 1
B41: Kara E Whittington, DDS Total | D41: 1 | E41: 1 | F41: 2
B42: Mark P Goldman, PhD | C42: Vijay Babu | D42: 1 | F42: 1
...

Sheet Error Details 
A3: Responsible_User_Status | B3: (All)
A4: Responsible_User_Name | B4: (All)
A6: Error Name | B6: Total Error occurrences
A7: Major-Incorrect Text/Gender/Names | B7: 95
A8: Major-Omitted/Inserted Text | B8: 33
A9: Major-Spelling Error | B9: 3
A10: Major-Drug/Medical Error | B10: 4
A11: Major-Demographics/Formatting/Protocol | B11: 1
A12: Major-Number/Value/Dates | B12: 16
A13: Grand Total | B13: 152

Sheet Responsible MT Details
F2: T/F | G2: FALSE
B3: Occurrences of Error | C3: UserStatus
B4: Responsible User Name / Error Name | C4: mt_new | D4: Grand Total
B5: Shiny Iype | C5: 47 | D5: 47 | F5: User Name | G5: Go | H5: NoGo | I5: Grand Total
B6: Major-Omitted/Inserted Text | C6: 23 | D6: 23 | F6: mt_new
B7: Major-Incorrect Text/Gender/Names | C7: 18 | D7: 18 | F7: Usha M | G7: 15 | H7: 10 | I7: 25
B8: Major-Number/Value/Dates | C8: 5 | D8: 5 | F8: Tejas Patel | G8: 17 | H8: 8 | I8: 25
B9: Major-Spelling Error | C9: 1 | D9: 1 | F9: Sivasankari A | G9: 23 | H9: 2 | I9: 25
B10: Tejas Patel | C10: 22 | D10: 22 | F10: Shiny Iype | G10: 8 | H10: 17 | I10: 25
B11: Major-Incorrect Text/Gender/Names | C11: 15 | D11: 15 | F11: Sandeep S | G11: 20 | H11: 5 | I11: 25
B12: Major-Number/Value/Dates | C12: 5 | D12: 5 | F12: Gopal Rajith | G12: 23 | H12: 1 | I12: 24
B13: Major-Omitted/Inserted Text | C13: 2 | D13: 2 | F13: Vijay Babu | G13: 21 | H13: 2 | I13: 23
B14: Usha M | C14: 21 | D14: 21 | F14: Pratheep Kumar | G14: 15 | H14: 6 | I14: 21
B15: Major-Incorrect Text/Gender/Names | C15: 16 | D15: 16 | F15: Chintul Sutaria | G15: 9 | H15: 1 | I15: 10
B16: Major-Omitted/Inserted Text | C16: 2 | D16: 2 | F16: Savitha Arun | G16: 1 | I16: 1
B17: Major-Demographics/Formatting/Protocol | C17: 1 | D17: 1 | F17: Grand Total | G17: 152 | H17: 52 | I17: 204
B18: Major-Number/Value/Dates | C18: 1 | D18: 1
B19: Major-Spelling Error | C19: 1 | D19: 1
B20: Pratheep Kumar | C20: 13 | D20: 13
B21: Major-Incorrect Text/Gender/Names | C21: 9 | D21: 9
B22: Major-Omitted/Inserted Text | C22: 3 | D22: 3
B23: Major-Number/Value/Dates | C23: 1 | D23: 1
B24: Sivasankari A | C24: 7 | D24: 7
B25: Major-Incorrect Text/Gender/Names | C25: 5 | D25: 5
B26: Major-Drug/Medical Error | C26: 1 | D26: 1
B27: Major-Omitted/Inserted Text | C27: 1 | D27: 1
B28: Vijay Babu | C28: 7 | D28: 7
B29: Major-Incorrect Text/Gender/Names | C29: 5 | D29: 5
... B42: Grand Total | C42: 130 | D42: 130

Sheet Responsible QA Details
B1: T/F | C1: FALSE
B2: Responsible_User_Status | C2: (All) | J2: Responsible_User_Status | K2: qa_new
F4: NoGo/Go | J4: Responsible User / Error Name | K4: Error Type
B5: Responsible_User_Name | C5: First_Touch-1 | D5: Account_name | E5: Doctor | F5: Go | G5: NoGo | H5: Grand Total | J5: Major-Incorrect Text/Gender/Names
B6: Shiny Iype | C6: Shiny Iype | D6: Auburn Community Hospital | E6: Daniel Alexander, MD | F6: 1 | G6: 1 | H6: 2 | J6: Savitha Arun | K6: 11
E7: Kathi F Teixeira, MD | F7: 1 | H7: 1 | J7: Chintul Sutaria | K7: 7
D8: Auburn Community Hospital Total | F8: 2 | G8: 1 | H8: 3 | J8: Major-Drug/Medical Error
D9: Cardiology Associates Medical Group | E9: Brian Martinez, PAC | G9: 2 | H9: 2 | J9: Savitha Arun | K9: 1
E10: Craig Mansour, MD | G10: 3 | H10: 3 | J10: Vijay Babu | K10: 1
E11: Jeffrey C Brackett, MD, FACC | F11: 5 | G11: 3 | H11: 8 | J11: Major-Number/Value/Dates
E12: Melissa Murillo, PA | G12: 3 | H12: 3 | J12: Chintul Sutaria | K12: 1
D13: Cardiology Associates Medical Group Total | F13: 5 | G13: 11 | H13: 16 | J13: Major-Omitted/Inserted Text
D14: Department Of Health Services - Wisconsin | E14: Scott Trippe, Psy.D. | G14: 1 | H14: 1 | J14: Savitha Arun | K14: 1
D15: Department Of Health Services - Wisconsin Total | G15: 1 | H15: 1 | J15: Grand Total | K15: 22
D16: Fred V Lause, DPM | E16: Fred V Lause, DPM | G16: 4 | H16: 4
D17: Fred V Lause, DPM Total | G17: 4 | H17: 4
D18: MEDICAL RESOURCE CENTER | E18: Jules J Barefoot, | F18: 1 | H18: 1
D19: MEDICAL RESOURCE CENTER Total | F19: 1 | H19: 1
C20: Shiny Iype Total | F20: 8 | G20: 17 | H20: 25
B21: Shiny Iype Total | F21: 8 | G21: 17 | H21: 25
B22: Usha M | C22: Usha M | D22: Adirondack Medical Center | E22: Eve Burns, MD | G22: 1 | H22: 1
E23: Jeffrey Dodge, DO | F23: 1 | H23: 1
E24: John Decker, MD | F24: 1 | H24: 1
E25: William Smith, MD | F25: 1 | G25: 1 | H25: 2
D26: Adirondack Medical Center Total | F26: 3 | G26: 2 | H26: 5
D27: Harmon Medical And Rehabilitation Hospital | E27: Gnaneswer Billakanti, MD | F27: 1 | H27: 1
D28: Harmon Medical And Rehabilitation Hospital Total | F28: 1 | H28: 1
D29: Hillsboro Area Hospital | E29: Blake Little, MD | G29: 1 | H29: 1
E30: Joel Wietfeldt, MD | G30: 1 | H30: 1
E31: Joseph Blaser, DO | F31: 4 | H31: 4
D32: Hillsboro Area Hospital Total | F32: 4 | G32: 2 | H32: 6
D33: Peterson Regional Medical Center | E33: Emmett R Mackan, MD | F33: 2 | H33: 2
E34: Kara E Whittington, DDS | F34: 1 | H34: 1
E35: Mark P Goldman, PhD | G35: 1 | H35: 1
E36: Melissa G Wampler, MD | G36: 1 | H36: 1
E37: Michael E Guerra, MD | F37: 1 | H37: 1
E38: Paul Valenza, DPM | G38: 1 | H38: 1
E39: Ralph J Fritzsch, MD | F39: 1 | H39: 1
E40: Ryan J Veurink, MD | F40: 1 | H40: 1
D41: Peterson Regional Medical Center Total | F41: 6 | G41: 3 | H41: 9
...

Sheet Tejas Patel's Error Details
A1: Auditor_name | B1: Devang Thakkar
A2: T/F | B2: FALSE
A4: Total_error_type_receiver_by_auditor | B4: Hospital Names
B5: DHS | E5: AMC | L5: RMCA | P5: LAC | T5: CAMG | U5: OHH | W5: NCSB | AB5: HMRH | AD5: MRC | AE5: PRMC | AG5: Auburn HIM | AH5: SMH | AI5: HAH | AK5: FVLD | AL5: SSH | AM5: MJHS | AO5: CRNRC | AQ5: HHRC | AR5: TKFC | AS5: SMCO | AU5: AMS | AV5: Grand Total
A6: Responsible User Name / Error Name | B6: PSYCHOLOGICAL REPORT | C6: Internal Medicine | D6: Dr Jankus Ortho | E6: ENT Clinic History and Physical | F6: Generic Operative Report | G6: Discharge Summary | H6: History and Physical | I6: SLEEP STUDY | J6: ENT Clinic Follow-Up | K6: STRESS TEST REPORT | L6: RMCA_OP | M6: RMCA_SLEEP_STUDY | N6: RMCA_NUCLEAR_STRESS | O6: RMCA_PFT | P6: LONGBEACH_Clinic Notes | Q6: GLENDALE_Clinic Notes | R6: GARDENA_Clinic Notes | S6: SANPEDRO_Clinic Notes | T6: CAMG_OV | U6: Clinic Template (OHH) | V6: Discharge Summary (OHH) | W6: Integrated Care Unit_Progress Note_3 | X6: PACT_Progress Note 2 | Y6: SA_Progress Note | Z6: Pediatric_Initial Psychiatric Evaluation | AA6: Cost Center CAS ICARE | AB6: Psychiatric Assessment | AC6: History & Physical | AD6: Independent Medical Examination | AE6: Operative Report | AF6: Consultation | AG6: Operative Report | AH6: Operative Report | AI6: HAH_OP | AJ6: HAH_SLEEP | AK6: Office Visits | AL6: Operative Report | AM6: Progress Note (Nursing Home) | AN6: History and Physical (Nursing Home) | AO6: Consultation | AP6: Discharge Summary | AQ6: History & Physical | AR6: OV | AS6: NEUROLOGY EXAM | AT6: Internal Medicine | AU6: Office Visit
A7: Minor-Punctuation/Grammar/Feedback | B7: 62 | C7: 6 | D7: 5 | E7: 1 | F7: 23 | G7: 4 | H7: 1 | I7: 1 | J7: 2 | K7: 2 | L7: 3 | M7: 2 | N7: 1 | O7: 1 | P7: 3 | Q7: 1 | R7: 2 | S7: 1 | T7: 119 | U7: 16 | V7: 8 | W7: 3 | X7: 5 | Y7: 2 | Z7: 4 | AA7: 6 | AB7: 9 | AC7: 4 | AD7: 15 | AE7: 13 | AF7: 2 | AG7: 10 | AH7: 2 | AI7: 2 | AJ7: 1 | AK7: 16 | AL7: 6 | AM7: 2 | AN7: 2 | AO7: 2 | AP7: 9 | AQ7: 4 | AR7: 5 | AS7: 1 | AU7: 2 | AV7: 391
A8: Shiny Iype | B8: 18 | T8: 63 | AD8: 4 | AG8: 10 | AK8: 9 | AV8: 104
A9: Chintul Sutaria | B9: 20 | C9: 2 | T9: 10 | V9: 8 | AD9: 4 | AK9: 7 | AM9: 2 | AN9: 2 | AR9: 5 | AS9: 1 | AV9: 61
A10: Tejas Patel | B10: 17 | D10: 5 | T10: 19 | AD10: 7 | AV10: 48
A11: Savitha Arun | F11: 4 | U11: 16 | Y11: 2 | AB11: 2 | AE11: 3 | AL11: 4 | AP11: 9 | AU11: 2 | AV11: 42
A12: Pratheep Kumar | B12: 6 | C12: 4 | T12: 27 | AV12: 37
A13: Usha M | E13: 1 | F13: 6 | G13: 2 | AC13: 1 | AE13: 7 | AF13: 1 | AH13: 2 | AL13: 2 | AV13: 22
A14: Vijay Babu | B14: 1 | F14: 13 | H14: 1 | J14: 2 | K14: 2 | AI14: 2 | AV14: 21
A15: Gopal Rajith | L15: 3 | M15: 2 | N15: 1 | O15: 1 | AB15: 6 | AO15: 2 | AQ15: 4 | AV15: 19
A16: Sandeep S | G16: 2 | I16: 1 | P16: 3 | Q16: 1 | R16: 2 | S16: 1 | AB16: 1 | AC16: 3 | AE16: 3 | AF16: 1 | AJ16: 1 | AV16: 19
A17: Sivasankari A | W17: 3 | X17: 5 | Z17: 4 | AA17: 6 | AV17: 18
A18: Major-Incorrect Text/Gender/Names | B18: 2 | L18: 1 | W18: 2 | AE18: 1 | AI18: 2 | AM18: 1 | AV18: 9
A19: Sivasankari A | W19: 2 | AV19: 2
A20: Usha M | AI20: 2 | AV20: 2
A21: Sandeep S | AE21: 1 | AV21: 1
A22: Chintul Sutaria | B22: 1 | AV22: 1
A23: Tejas Patel | B23: 1 | AV23: 1
A24: Savitha Arun | AM24: 1 | AV24: 1
A25: Gopal Rajith | L25: 1 | AV25: 1
A26: Major-Number/Value/Dates | T26: 1 | AF26: 2 | AJ26: 1 | AT26: 1 | AV26: 5
A27: Sandeep S | AJ27: 1 | AV27: 1
A28: Vijay Babu | AF28: 1 | AV28: 1
A29: Chintul Sutaria | AT29: 1 | AV29: 1
A30: Shiny Iype | T30: 1 | AV30: 1
A31: Usha M | AF31: 1 | AV31: 1
A32: Major-Drug/Medical Error | J32: 1 | AV32: 1
A33: Vijay Babu | J33: 1 | AV33: 1
A34: Major-Demographics/Formatting/Protocol | AJ34: 1 | AV34: 1
A35: Usha M | AJ35: 1 | AV35: 1
A36: Major-Omitted/Inserted Text | W36: 1 | AV36: 1
A37: Sivasankari A | W37: 1 | AV37: 1
A38: Grand Total | B38: 64 | C38: 6 | D38: 5 | E38: 1 | F38: 23 | G38: 4 | H38: 1 | I38: 1 | J38: 3 | K38: 2 | L38: 4 | M38: 2 | N38: 1 | O38: 1 | P38: 3 | Q38: 1 | R38: 2 | S38: 1 | T38: 120 | U38: 16 | V38: 8 | W38: 6 | X38: 5 | Y38: 2 | Z38: 4 | AA38: 6 | AB38: 9 | AC38: 4 | AD38: 15 | AE38: 14 | AF38: 4 | AG38: 10 | AH38: 2 | AI38: 4 | AJ38: 3 | AK38: 16 | AL38: 6 | AM38: 3 | AN38: 2 | AO38: 2 | AP38: 9 | AQ38: 4 | AR38: 5 | AS38: 1 | AT38: 1 | AU38: 2 | AV38: 408

Sheet Group
A1: Sr.No | B1: Account NAme | C1: Hospital Initial | D1: India MTTL | E1: US MTTL | F1: Top 25 | G1: Group | H1: New Initial
A2: 1 | B2: Alice Hyde Memorial Hospital | C2: AHMH | D2: Aneesh | E2: Jerri | F2: Top 25 | G2: Top 25 | H2: AHMH
A3: =A2+1 -> 2 | B3: Adirondack Medical Center | C3: AMC | D3: Aneesh | E3: Jerri | F3: Top 25 | G3: AMC Group | H3: AMC
A4: =A3+1 -> 3 | B4: Amiel Levin MD | C4: AML | D4: Harsh | E4: Jerri | F4: Others | G4: Others | H4: Others
A5: =A4+1 -> 4 | B5: Anderson Regional Medical Center | C5: ARMC | D5: Ankit | E5: Jerri | F5: Others | G5: Others | H5: Others
A6: =A5+1 -> 5 | B6: Auburn Community Hospital | C6: Auburn HIM | D6: Ankit | E6: Jerri | F6: Others | G6: Others | H6: Auburn HIM
A7: =A6+1 -> 6 | B7: Barlow Respiratory Hospital | C7: BRH | D7: Ankit | E7: Jerri | F7: Others | G7: Others | H7: BRH
A8: =A7+1 -> 7 | B8: Cardiology Associates Medical Group | C8: CAMG | D8: Harsh | E8: Jerri | F8: Top 25 | G8: Top 25 | H8: CAMG
A9: =A8+1 -> 8 | B9: Crenshaw Community Hospital | C9: CCH | D9: Ankit | E9: Jerri | F9: Top 25 | G9: Top 25 | H9: CCH
A10: =A9+1 -> 9 | B10: Charles Cole Memorial Hospital | C10: CCM | D10: Ankit | E10: Jerri | F10: Top 25 | G10: Top 25 | H10: CCM
A11: =A10+1 -> 10 | B11: Central Desert Behavioral Health Ct | C11: CDBHC | D11: Aneesh | E11: Jerri | F11: Top 25 | G11: Fundamental | H11: Fundamental
A12: =A11+1 -> 11 | B12: Coon Memorial Hospital | C12: COON | D12: Harsh | E12: Jerri | F12: Others | G12: Others | H12: Others
A13: =A12+1 -> 12 | B13: Copiah County Medical Center | C13: COPIAH | D13: Purvang | E13: Jerri | F13: Others | G13: Others | H13: Copiah
A14: =A13+1 -> 13 | B14: The Central Ohio Urology | C14: COUG | D14: Harsh | E14: Jerri | F14: Others | G14: COUG Group | H14: COUG
... A69: =A68+1 -> 68 | B69: Wyoming State Hospital | C69: WSH | D69: Aneesh | E69: Jerri | F69: Others | G69: Others | H69: Others
A70: =A69+1 -> 69 | B70: Mmodal | C70: Mmodal | D70: Ankit | F70: Top 25 | G70: Top 25 | H70: 0
A71: =A70+1 -> 70 | B71: Wellstar | C71: Wellstar | D71: Ankit | H71: 0
A72: =A71+1 -> 71 | B72: Dr Askins | C72: DRASK | D72: Harsh | E72: Jerri | F72: Others | G72: Others | H72: Others
A73: =A72+1 -> 72 | B73: Nemours Children's Specialty Care Clinic | C73: NCSCC | D73: Harsh | E73: Jerri | F73: Others | G73: Others | H73: Others
A74: =A73+1 -> 73 | B74: Sweeney Spine | C74: SWS | D74: Harsh | E74: Jerri | F74: Others | G74: Others | H74: Others
A75: =A74+1 -> 74 | B75: Elena Antonelli, MD | C75: EAM | D75: Ankit | E75: Jerri | F75: Others | G75: Others | H75: Others
A76: =A75+1 -> 75 | B76: Fred V Lause, DPM | C76: FVLD | D76: Ankit | E76: Jerri | F76: Others | G76: Others | H76: Others
A77: =A76+1 -> 76 | B77: Springfield Trauma Counseling Center | C77: STCC | D77: Harsh | E77: Jerri | F77: Others | G77: Others | H77: Others
A78: =A77+1 -> 77 | B78: Brian Gruber, MD | C78: BRIAN | D78: Harsh | E78: Jerri | F78: Others | G78: Others | H78: Others
A79: =A78+1 -> 78 | B79: UT Health Austin | C79: UTHA | D79: Harsh | E79: Jerri | F79: Others | G79: Others | H79: Others
A80: =A79+1 -> 79 | B80: The Klingberg Family Centers | C80: TKFC | D80: Harsh | E80: Jerri | F80: Others | G80: Others | H80: Others
A81: =A80+1 -> 80 | B81: NORTH CHICAGO, FHCC | C81: NHC | D81: Aneesh | E81: Jerri | F81: Others | G81: Others | H81: Others
A82: =A81+1 -> 81 | B82: SALEM VA MEDICAL CENTER | C82: SMC | D82: Purvang | E82: Jerri | F82: Others | G82: Others | H82: Others
A83: =A82+1 -> 82 | B83: Aerete Integrative Medicine | C83: AIM | D83: Aneesh | E83: Jerri | F83: Others | G83: Others | H83: Others
... A147: =A146+1 -> 146 | B147: WILMINGTON | C147: WNN | D147: Ankit | E147: Jerri | F147: Alpha Transcription | G147: Alpha Transcription | H147: Others
A148: =A147+1 -> 147 | B148: Noelle Thomas, MD | C148: NTS | D148: Aneesh | E148: Jerri | F148: Others | G148: Others | H148: #N/A
A149: =A148+1 -> 148 | B149: LA County GT | C149: LAGT | D149: Harsh | E149: Jerri | F149: Others | G149: Others | H149: Others
A150: =A149+1 -> 149 | B150: LAS VEGAS | C150: LVS | D150: Ankit | E150: Jerri | F150: Alpha Transcription | G150: Alpha Transcription | H150: Others
A151: =A150+1 -> 150 | B151: Promise Healthcare | C151: PHE | D151: Ankit | E151: Jerri | F151: Others | G151: Others | H151: Others
A152: 151 | B152: Kentuckiana Medical Center | C152: KMC | D152: Harsh | E152: Jerri | F152: Others | G152: Others | H152: Others
A153: 152 | B153: Springbrook Behavioral Health System | C153: SBHS | D153: Harsh | E153: Jerri | F153: Others | G153: Others | H153: Others
A154: =A153+1 -> 153 | B154: Cassol Eye | C154: CEE | D154: Harsh | E154: Jerri | F154: Others | G154: Others | H154: Others
A155: =A154+1 -> 154 | B155: Sagebrush Medical Consultants | C155: SMCO | D155: Harsh | E155: Jerri | F155: Others | G155: Others | H155: Top 25
A156: =A155+1 -> 155 | B156: Barlow Respiratory Hospital VPH - 232 | C156: Barlow | D156: Harsh | E156: Jerri | F156: Top 25 | G156: Top 25 | H156: Top 25
A157: =A156+1 -> 156 | B157: WCMC - White County Medical Center Cardi | C157: WCMC | D157: Harsh | E157: Jerri | F157: Top 25 | G157: Top 25 | H157: Top 25
...

Sheet others
A1: Sr. No | B1: EZMediscribes | C1: Name | D1: EZMediscribes | E1: Initials | F1: Target | G1: Desg | H1: Status | I1: Timing | J1: Shift | K1: Weekoff | L1: Primary | M1: Secondary | N1: Tertiary | O1: Location | P1: TL | Q1: Email id | R1: Personal Email ID | S1: Skype ID | T1: Mobile number
A2: 1 | B2: vvdeepak | C2: Deepak V | D2: vvdeepak | E2: idv-t | F2: 576 | G2: MTX - India | H2: DIRECT | I2: 9 p.m. to 5 a.m. | J2: Night | K2: Saturday/Sunday Alternate | L2: AMC | M2: PRMC | N2: IMPH, OIP | O2: Trivandrum | P2: Aneesh | Q2: deepak.v@cardioscribes.com | T2: 9633682450
A3: =+A2+1 -> 2 | B3: dileeps | C3: Dileep S | D3: dileeps | E3: ids-t | F3: 641 | G3: MTX - India | H3: DIRECT | I3: 5 a.m. to 2 p.m. | J3: Day | K3: Sunday-Monday Alternate | L3: AMC | M3: PRMC | N3: IMPH, GMHS, HAH, OIP, LAC, OUP | O3: Trivandrum | P3: Aneesh | Q3: dileep.s@cardioscribes.com | T3: 9847888449
A4: =+A3+1 -> 3 | B4: febinc | C4: Febin Clament | D4: febinc | E4: ifbc-t | F4: 500 | G4: MTX - India | H4: DIRECT | I4: 7 a.m. to 3 p.m. | J4: Day | K4: Sunday/Monday | L4: GMHS | M4: Fundamentals, IMPH, OIP, LAC | N4: NA | O4: Trivandrum | P4: Aneesh | Q4: febin.clament@cardioscribes.com | T4: 8606038897 / 8089759380
A5: =+A4+1 -> 4 | B5: giginp | C5: Gigin Prakash | D5: giginp | E5: igp-t | F5: 480 | G5: MTX - India | H5: DIRECT | I5: 7:30 a.m. to 3:30 p.m. | J5: Day | K5: Monday | L5: Fundamentals | M5: WSH | N5: OIP, IMPH | O5: Trivandrum | P5: Aneesh | Q5: giginmediscribes@gmail.com | T5: 9995251764
A6: =+A5+1 -> 5 | B6: lakshmi | C6: Lakshmi M | D6: lakshmi | E6: ila | F6: 454 | G6: MTx-India | H6: DIRECT | I6: 4:30 a.m. to 12:30 p.m. | J6: Day | K6: Sunday-Monday Alternate | L6: Fundamentals | M6: OUP | N6: WSH | O6: Trivandrum | P6: Aneesh | Q6: lakshmi.gm@cardioscribes.com | T6: 9495370068
A7: =+A6+1 -> 6 | B7: mercya | C7: MERCY ARUN | D7: mercya | E7: ima-t | F7: 1357 | G7: QA - India | H7: DIRECT | I7: 9 am to 6 pm | J7: Day | K7: Sunday-Monday Alternate | L7: AMC | M7: All TVM accounts | O7: Trivandrum | P7: Aneesh | Q7: mercy.arun@cardioscribes.com | T7: 9895343700
A8: =+A7+1 -> 7 | B8: nitheeshc | C8: Nitheesh C | D8: nitheeshc | E8: inc-t | F8: 750 | G8: MTX - India | H8: DIRECT | I8: 7 a.m. to 3 p.m. | J8: Day | K8: Saturday/Sunday Alternate | L8: AMC | M8: PRMC, IMPH | N8: GMHS, OIP, SRH | O8: Trivandrum | P8: Aneesh | Q8: nitheesh.c@cardioscribes.com | T8: 9037446942
A9: =+A8+1 -> 8 | B9: sprasanth | C9: Prasanth Sivan | D9: sprasanth | E9: ips-t | F9: 576 | G9: MTX - India | H9: DIRECT | I9: 5:30 a.m. to 2 p.m. | J9: Day | K9: Sunday-Monday Alternate | L9: AMC | M9: PRMC | N9: GMHS, OIP, IMPH | O9: Trivandrum | P9: Aneesh | Q9: prasanth.sivan@cardioscribes.com | T9: 8921645118
A10: =+A9+1 -> 9 | B10: rrenjini | C10: Renjini Raj | D10: rrenjini | E10: irr-t | F10: LINE COUNT | G10: MTX - India | H10: DIRECT | I10: 9 p.m. to 5 a.m. | J10: Night | K10: Sunday | L10: Fundamentals | M10: Copiah | N10: NA | O10: Trivandrum | P10: Aneesh | Q10: chellu_ren@yahoo.co.in | T10: 8129007920
A11: =+A10+1 -> 10 | B11: ssandeep | C11: Sandeep S | D11: ssandeep | E11: isan-t | F11: 683 | G11: MTX - India | H11: DIRECT | I11: 6:30 p.m. to 2:30 a.m. | J11: Day | K11: Sunday-Monday Alternate | L11: AMC | M11: PRMC | N11: IMPH, GMHS, SRH, OIP, LAC | O11: Trivandrum | P11: Aneesh | Q11: sandeep.s@cardioscribes.com | T11: 9747673817
A12: =+A11+1 -> 11 | B12: sarun | C12: SAVITHA ARUN | D12: sarun | E12: isar-t | F12: 1600 | G12: QA - India | H12: DIRECT | I12: 4:30 a.m. to 1 p.m. | J12: Day | K12: Sunday-Monday Alternate | L12: PRMC | M12: All TVM accounts | O12: Trivandrum | P12: Aneesh | Q12: savitha.arun@cardioscribes.com | T12: 8893252247
A13: =+A12+1 -> 12 | B13: vipins | C13: Vipin S | D13: vipins | E13: ivps-t | F13: 427 | G13: MTX - India | H13: DIRECT | I13: 4:30 a.m. to 12:30 p.m. | J13: Day | K13: Sunday-Monday Alternate | L13: Fundamentals | M13: WSH | N13: NA | O13: Trivandrum | P13: Aneesh | Q13: vipinvsprajapathy@gmail.com | T13: 9544421751
A14: =+A13+1 -> 13 | B14: jagranathj | C14: Jagranath Jha | D14: jagranathj | E14: ijj | F14: 682 | G14: MTX - India | H14: Needs QA | I14: 4 a.m. to 12 p.m. | J14: Day | K14: Sunday-Monday Alternate | L14: BRH | M14: COON/SHIFA | N14: NMH/CCH/CCM | O14: Ahmedabad | P14: Ankit | Q14: jagranath.j@cardioscribes.com | T14: 9831263018
A15: =+A14+1 -> 14 | B15: Tharsh | C15: Tushar Harsh | D15: Tharsh | E15: ihtj | F15: 560 | G15: MTX - India | H15: DIRECT | I15: 8 a.m. to 4 p.m. | J15: Day | K15: Sunday-Monday Alternate | L15: COUG/COUSC | M15: MMC/CVG/CVAMD | N15: TKFC/RVM | O15: Ahmedabad | P15: Harsh | Q15: tushar.harsh@cardioscribes.com | T15: 9687608383
A16: =+A15+1 -> 15 | B16: shinyi | C16: Shiny Iype | D16: shinyi | E16: iis | F16: 654 | G16: MTX - India | H16: DIRECT | I16: 8 a.m. to 4 p.m. | J16: Day | K16: Sunday-Monday Alternate | L16: Auburn-HIM | M16: FLVD | N16: HVS/CRENSAW/Lora/DHS MMC | O16: Ahmedabad | P16: Ankit | Q16: shiny.iype@cardioscribes.com | T16: 8460285290
A17: =+A16+1 -> 16 | B17: riteshp | C17: Riteshkumar Patel | D17: riteshp | F17: 669 | G17: MTX - India | H17: DIRECT | I17: 10 P.M. TO 6 A.M. | J17: Night | K17: Monday | L17: BRH | M17: SVH/CVG | N17: NLC | O17: Ahmedabad | P17: Ankit | Q17: Ritesh.Patel@cardioscribes.com | T17: 8401201594 \ 9925771028
A18: =+A17+1 -> 17 | B18: ptrivedi | C18: PURVANG TRIVEDI | D18: ptrivedi | E18: ipt | F18: TL | G18: TL | H18: DIRECT | J18: TL | K18: Saturday | L18: Multiple Accounts | M18: NA | N18: NA | O18: Ahmedabad | P18: Harsh | Q18: purvang.trivedi@cardioscribes.com | T18: 9137120712
A19: =+A18+1 -> 18 | B19: arunaj | C19: Aruna Arun | D19: arunaj | E19: iajad | F19: LINE COUNT | G19: BB-QA - India | H19: DIRECT | I19: 7 pm to 10 pm | J19: Night | K19: Sunday | L19: Multiple Accounts | M19: NA | N19: NA | O19: Ahmedabad | P19: Harsh | Q19: Jitendra.Nim@cardioscribes.com | T19: 9825582502
A20: =+A19+1 -> 19 | B20: sharmab | C20: Bhakti Sharma | D20: sharmab | E20: ibys | F20: LINE COUNT | G20: MTX - India | H20: DIRECT | I20: 10 am to 4 pm | J20: Day | K20: Sunday | L20: HCA | M20: NA | N20: NA | O20: Ahmedabad | P20: Harsh | Q20: bhaktisharma1@yahoo.co.in | T20: 9910236455
A21: =+A20+1 -> 20 | B21: gunjanc | C21: GUNJAN CHAWDA | D21: gunjanc | E21: igpc | F21: 1417 | G21: QA - India | H21: DIRECT | I21: 8 pm to 4 am | J21: Night | K21: Saturday | L21: All | M21: NA | N21: NA | O21: Ahmedabad | P21: Ankit | Q21: gunjan.chavda@cardioscribes.com | T21: 9375439960
A22: =+A21+1 -> 21 | B22: doubtdt | C22: Devang ThakkarBB | D22: doubtdt | E22: idvtd | F22: LINE COUNT | G22: BB-QA - India | H22: DIRECT | I22: 7 am to 9 am | J22: Day | K22: NA | L22: Multiple Accounts | M22: NA | N22: NA | O22: Ahmedabad | P22: Harsh | Q22: devang.thakker@cardioscribes.com | T22: 9825653232
A23: =+A22+1 -> 22 | B23: mazhart | C23: Mazhar Tinwala | D23: mazhart | E23: imnt | F23: 1919 | G23: QA - India | H23: DIRECT | I23: 8 am to 4 pm | J23: Day | K23: Sunday-Monday Alternate | L23: All Accounts | N23: NA | O23: Ahmedabad | P23: Harsh | Q23: mazhar.tinwala@cardioscribes.com | T23: 9924135228
A24: =+A23+1 -> 23 | B24: parvej | C24: Parvez Shaikh | D24: parvej | E24: isp | F24: 767 | G24: MTX - India | H24: DIRECT | I24: 9 A.M. To 6 P.M. | J24: Day | K24: Sunday-Monday Alternate | L24: CAMG | M24: FHG/WOS | N24: SVH | O24: Ahmedabad | P24: Harsh | Q24: parvez.shaikh@cardioscribes.com | T24: 98246-95885
A25: =+A24+1 -> 24 | B25: pdesai | C25: Pranav Desai | D25: pdesai | E25: ipd | F25: 661 | G25: MTX - India | H25: DIRECT | I25: 10 A.M. TO 6 P.M. | J25: Day | K25: Sunday-Monday Alternate | L25: CAMG | M25: HCA | N25: CVAMD/SVH | O25: Ahmedabad | P25: Harsh | Q25: pranav.desai@cardioscribes.com | T25: 99254-99193
A26: =+A25+1 -> 25 | B26: rmodha | C26: Rajesh Modha | D26: rmodha | E26: irm | F26: 437 | G26: MTX - India | H26: DIRECT | I26: 10 A.M. TO 6 P.M. | J26: Day | K26: Sunday-Monday Alternate | L26: CAMG | M26: HCA | N26: CVAMD/SVH | O26: Ahmedabad | P26: Harsh | Q26: rajesh.modha@cardioscribes.com | T26: 97127-59638
A27: =+A26+1 -> 26 | B27: Renishb | C27: RENISH BHAIRAPURE | D27: Renishb | E27: irbb | F27: 1497 | G27: QA - India | H27: DIRECT | I27: 4 A.M. To 12 P.M. | J27: Day | K27: Sunday-Monday Alternate | L27: All account | O27: Ahmedabad | P27: Ankit | Q27: renish.bhairapure@cardioscribes.com | T27: 9925035143
A28: =+A27+1 -> 27 | B28: SANTOSH | C28: Santosh Singh | D28: SANTOSH | E28: isks | F28: 1948 | G28: QA - India | H28: DIRECT | I28: 1 p.m. to 8 p.m. | J28: Day | K28: Sunday-Monday Alternate | L28: All account | M28: ALL | N28: ALL | O28: Ahmedabad | P28: Harsh | Q28: santosh.singh@cardioscribes.com | T28: 9586560199
A29: =+A28+1 -> 28 | B29: shrikantc | C29: SHRIKANT CHANDAK | D29: shrikantc | E29: iscd | F29: 3787 | G29: BB-QA - India | H29: DIRECT | I29: 10 p.m. to 6 a.m. | J29: Night | K29: Sunday | L29: ALL | M29: NA | N29: NA | O29: Ahmedabad | P29: Harsh | Q29: shrikant.c@cardioscribes.com | T29: 9924124240
A30: =+A29+1 -> 29 | B30: shwetap | C30: Shweta Parmar | D30: shwetap | E30: iskp | F30: 795 | G30: MTX - India | H30: DIRECT | I30: 9.00 A.M. TO 7 P.M. | J30: Day | K30: Sunday-Monday Alternate | L30: HCA | M30: NLC | N30: FHG/NSCA | O30: Ahmedabad | P30: Harsh | Q30: shweta.parmar@cardioscribes.com | T30: 9998077837/9724540977
A31: =+A30+1 -> 30 | B31: Sonali | C31: Sonali Patel | D31: Sonali | E31: ajv | F31: 795 | G31: MTX - India | H31: DIRECT | I31: 10 A.M. To 6 P.M. | J31: Day | K31: Sunday-Monday Alternate | L31: HCA | M31: NLC | N31: NSCA | O31: Ahmedabad | P31: Harsh | Q31: sonali.patel@cardioscribes.com | T31: 94281-13951/7069034599
A32: =+A31+1 -> 31 | B32: Agajjar | C32: Aarti Gajjar | D32: Agajjar | E32: iadj | F32: 302 | G32: VR - MT | H32: DIRECT | I32: 10 am to 6 pm | J32: Day | K32: Sunday | L32: CVG | M32: HCA | N32: KCPC | O32: Ahmedabad | P32: Harsh | Q32: aarti.gajjar@cardioscribes.com | T32: 9879306349
A33: =+A32+1 -> 32 | B33: Mchauhan | C33: Meera Chauhan | D33: Mchauhan | E33: imvc | F33: LINE COUNT | G33: VR - MT | H33: DIRECT | I33: 10 am to 6 pm | J33: Day | K33: Sunday | L33: CVG/COUG | M33: CAMG/NLC | N33: NSCA | O33: Ahmedabad | P33: Harsh | Q33: meera.chauhan@cardioscribes.com | T33: 9913432171
A34: =+A33+1 -> 33 | B34: Pthakore | C34: Purvi Thakore | D34: Pthakore | E34: ipyt | F34: 1104 | G34: VR - MT | H34: DIRECT | I34: 10 am to 6 pm | J34: Day | K34: Sunday | L34: CVG/CAMG/COUG | M34: Dr. Chino | N34: Auburn/Cophia/TKFC | O34: Ahmedabad | P34: Harsh | Q34: purvi.thakore@cardioscribes.com | T34: 9825564916
A35: =+A34+1 -> 34 | B35: Vprajapati | C35: Vikram Prajapati | D35: Vprajapati | E35: ivhp | F35: 994 | G35: MTX - India | H35: DIRECT | I35: 9 A.M. To 5 P.M. | J35: Day | K35: Monday | L35: CVG | M35: NOCH/MMH | N35: Auburn/HCC/TKFC/RVM | O35: Ahmedabad | P35: Harsh | Q35: vikram.prajapati@cardioscribes.com | T35: 98250-25878
A36: =+A35+1 -> 35 | B36: afaiz | C36: FAIZ AHMAD | D36: afaiz | E36: iaf | F36: 1390 | G36: QA - India | H36: DIRECT | I36: 10 p.m. - 6 a.m. | J36: Night | K36: Monday | L36: ALL ACCOUNTS | O36: Ahmedabad | P36: Ankit | Q36: faiz.ahmad@cardioscribes.com | T36: 8271144857
A37: =+A36+1 -> 36 | B37: Gthakkar | C37: Gaurang Thakkar | D37: Gthakkar | E37: igst | F37: 781 | G37: MTX - India | H37: DIRECT | I37: 7 am to 3 pm | J37: Day | K37: Sunday-Monday Alternate | L37: WOS/CAMG | M37: NOCH/SVH | N37: Healthwin/Coon | O37: Ahmedabad | P37: Harsh | Q37: gaurang.thakkar@cardioscribes.com | T37: 9328888983
A38: =+A37+1 -> 37 | B38: girishs | C38: Girish S | D38: girishs | E38: igis | F38: 606 | G38: MTX - India | H38: DIRECT | I38: 8:00 p.m. to 4:00 a.m. | J38: Night | K38: Monday | L38: MJHS, NOCH, RMCA | M38: SVH, NSCA, COUG, OGH | N38: PMH, BRH, CVPH | O38: Ahmedabad | P38: Ankit | Q38: girish.s@cardioscribes.com | T38: 7760758231
A39: =+A38+1 -> 38 | B39: preethau | C39: Preetha Uchil | D39: preethau | E39: ipau | F39: 739 | G39: MTX - India | H39: DIRECT | I39: 6 a.m. to 2 p.m. | J39: Day | K39: Monday | L39: WFA/OGH/SMA/KCPC/TNA | M39: Dr.Askins/CVG/SWS/HCA | N39: CVPH//TKFC/COUG/MMH | O39: Ahmedabad | P39: Harsh | Q39: preetha.uchil@cardioscribes.com | T39: 9323692241
A40: =+A39+1 -> 39 | B40: adiseshu | C40: Adiseshu T | D40: adiseshu | E40: iadi | F40: 750 | G40: MT - India | H40: Needs QA | I40: 8:30 pm to 5:30 Am | J40: Night | L40: AHMH/MJHS | M40: FMCH | N40: All Chennai accounts | O40: Trivandrum | P40: Aneesh | Q40: Venkataadiseshu.t@cardioscribes.com | T40: 8688905577
...

Sheet Data
A1: Received_Date_UTC | B1: Received_Date_IST | C1: Date_audited_UTC | D1: Date_audited_IST | E1: Auditor_Work_Start_Date_IST | F1: Auditor_Work_End_Date_IST | G1: Auditor_name | H1: Auditor_Screen_Time_Spend_In_Seconds | I1: Time_Taken_by_Auditor_in_mins | J1: Auditor_milestone | K1: File_name | L1: Doctor | M1: Account_name | N1: Subhospital | O1: Responsible_ID | P1: Responsible_User_Name | Q1: Location | R1: NoGo/Go_2010 | S1: Line Count | T1: Accuracy_2010 | U1: Error_Name | V1: Total_error_type_receiver_by_auditor | W1: Remarks | X1: Worktype | Y1: First_Touch | Z1: Time_Taken_First_Touch_mins | AA1: TAT | AB1: Is_Tough_Dictator | AC1: Play_Time_in_sec | AD1: SSTAT_STAT_Normal | AE1: Missed_Achieved | AF1: Final_Blank_Count | AG1: Second_Last_Touch | AH1: Time_Taken_Second_Touch_mins | AI1: Last_Touch | AJ1: Time_Taken_Last_Touch_mins | AK1: Audited Date | AL1: Week | AM1: Initial | AN1: NoGo/Go | AO1: Accuracy | AP1: Point value | AQ1: Overall Score | AR1: Account's MTTL | AS1: USer's MTTL | AT1: First touch MTTL | AU1: Error Type | AV1: Con | AW1: Name | AX1: Score | AY1: Location-1 | AZ1: T/F | BA1: Total Error Count | BB1: Total Error occurrences | BC1: First_Touch-1 | BD1: Responsible_User_Status | BE1: Sent Status Name | BF1: Match | BG1: Group | BH1: Responsible_User_Designation
A2: 46084.376 | B2: 46084.605 | C2: 46091.209 | D2: 46091.438 | E2: 46086.629 | F2: 46091.438 | G2: Devang Thakkar | H2: 291 | I2: 6923.8833 | J2: cqa | K2: 12825718 | L2: Joseph Blaser, DO | M2: Hillsboro Area Hospital | N2: Clinic | O2: veejay_b@yahoo.com | P2: Vijay Babu | Q2: Trivandrum | R2: Go | S2: 54.15 | T2: 100 | V2: 0 | X2: HAH_OP | AA2: 120 | AB2: No | AC2: 262 | AD2: Normal | AE2: Achieved | AF2: 0 | AK2: =INT(D2) -> 46091 | AL2: ="Week"&WEEKNUM(D2) -> Week11 | AM2: HAH | AN2: =IF(AO2>98.5,"Go","NoGo") -> Go | AO2: =100-(AQ2/S2*100) -> 100 | AP2: =IFERROR(AX2*V2,0) -> 0 | AQ2: =100-T2 -> 0 | AR2: Aneesh | AS2: Aneesh | AT2: Aneesh | AU2: =IF(AX2="","",IF(AX2=1,"Major",IF(AX2=3,"Critical",IF(AX2=0,"Minor","")))) | AV2: =K2&P2 -> 12825718Vijay Babu | AW2: =IF(U2="","",LEFT(U2,FIND("-",U2,1)-1)) | AX2: =IF(AW2="Minor",0,IF(AW2="Major",1,IF(AW2="Critical",3,""))) | AY2: Trivandrum | AZ2: FALSE | BA2: =IF(U2="","",COUNTIF(U2,U2:U2)) | BB2: =V2 -> 0 | BC2: Vijay Babu | BD2: mt_new | BE2: awaiting_upload | BF2: FALSE | BG2: =VLOOKUP(AM2,Group!$C:$H,5,0) -> Others | BH2: =VLOOKUP(P2,others!$C:$G,5,0) -> MTX - India
A3: 46084.536 | B3: 46084.765 | C3: 46091.213 | D3: 46091.443 | E3: 46086.63 | F3: 46091.443 | G3: Devang Thakkar | H3: 891 | I3: 6930.6 | J3: cqa | K3: 12825779 | L3: Joseph Blaser, DO | M3: Hillsboro Area Hospital | N3: Clinic | O3: veejay_b@yahoo.com | P3: Vijay Babu | Q3: Trivandrum | R3: Go | S3: 67.12 | T3: 100 | U3: Minor-Punctuation/Grammar/Feedback | V3: 2 | X3: HAH_OP | AA3: 120 | AB3: No | AC3: 297 | AD3: Normal | AE3: Achieved | AF3: 0 | AK3: =INT(D3) -> 46091 | AL3: ="Week"&WEEKNUM(D3) -> Week11 | AM3: HAH | AN3: =IF(AO3>98.5,"Go","NoGo") -> Go | AO3: =100-(AQ3/S3*100) -> 100 | AP3: =IFERROR(AX3*V3,0) -> 0 | AQ3: =100-T3 -> 0 | AR3: Aneesh | AS3: Aneesh | AT3: Aneesh | AU3: =IF(AX3="","",IF(AX3=1,"Major",IF(AX3=3,"Critical",IF(AX3=0,"Minor","")))) -> Minor | AV3: =K3&P3 -> 12825779Vijay Babu | AW3: =IF(U3="","",LEFT(U3,FIND("-",U3,1)-1)) -> Minor | AX3: =IF(AW3="Minor",0,IF(AW3="Major",1,IF(AW3="Critical",3,""))) -> 0 | AY3: Trivandrum | AZ3: FALSE | BA3: =IF(U3="","",COUNTIF(U3,U3:U3)) -> 1 | BB3: =V3 -> 2 | BC3: Vijay Babu | BD3: mt_new | BE3: awaiting_upload | BF3: FALSE | BG3: =VLOOKUP(AM3,Group!$C:$H,5,0) -> Others | BH3: =VLOOKUP(P3,others!$C:$G,5,0) -> MTX - India
A4: 46084.475 | B4: 46084.704 | C4: 46091.232 | D4: 46091.461 | E4: 46086.63 | F4: 46091.461 | G4: Devang Thakkar | H4: 13269 | I4: 6956.95 | J4: cqa | K4: 12825745 | L4: William Smith, MD | M4: Adirondack Medical Center | N4: Clinic | O4: veejay_b@yahoo.com | P4: Vijay Babu | Q4: Trivandrum | R4: Go | S4: 105.75 | T4: 100 | V4: 0 | X4: Generic Operative Report | AA4: 360 | AB4: No | AC4: 486 | AD4: Normal | AE4: Achieved | AF4: 0 | AK4: =INT(D4) -> 46091 | AL4: ="Week"&WEEKNUM(D4) -> Week11 | AM4: AMC | AN4: =IF(AO4>98.5,"Go","NoGo") -> Go | AO4: =100-(AQ4/S4*100) -> 100 | AP4: =IFERROR(AX4*V4,0) -> 0 | AQ4: =100-T4 -> 0 | AR4: Aneesh | AS4: Aneesh | AT4: Aneesh | AU4: =IF(AX4="","",IF(AX4=1,"Major",IF(AX4=3,"Critical",IF(AX4=0,"Minor","")))) | AV4: =K4&P4 -> 12825745Vijay Babu | AW4: =IF(U4="","",LEFT(U4,FIND("-",U4,1)-1)) | AX4: =IF(AW4="Minor",0,IF(AW4="Major",1,IF(AW4="Critical",3,""))) | AY4: Trivandrum | AZ4: FALSE | BA4: =IF(U4="","",COUNTIF(U4,U4:U4)) | BB4: =V4 -> 0 | BC4: Vijay Babu | BD4: mt_new | BE4: awaiting_upload | BF4: FALSE | BG4: =VLOOKUP(AM4,Group!$C:$H,5,0) -> AMC Group | BH4: =VLOOKUP(P4,others!$C:$G,5,0) -> MTX - India
A5: 46084.482 | B5: 46084.711 | C5: 46091.246 | D5: 46091.475 | E5: 46086.63 | F5: 46091.475 | G5: Devang Thakkar | H5: 2972 | I5: 6976.7833 | J5: cqa | K5: 12825757 | L5: William Smith, MD | M5: Adirondack Medical Center | N5: Clinic | O5: veejay_b@yahoo.com | P5: Vijay Babu | Q5: Trivandrum | R5: No Go | S5: 134.58 | T5: 98 | U5: Major-Incorrect Text/Gender/Names | V5: 2 | X5: Generic Operative Report | AA5: 360 | AB5: No | AC5: 600 | AD5: Normal | AE5: Achieved | AF5: 2 | AK5: =INT(D5) -> 46091 | AL5: ="Week"&WEEKNUM(D5) -> Week11 | AM5: AMC | AN5: =IF(AO5>98.5,"Go","NoGo") -> Go | AO5: =100-(AQ5/S5*100) -> 98.513895 | AP5: =IFERROR(AX5*V5,0) -> 2 | AQ5: =100-T5 -> 2 | AR5: Aneesh | AS5: Aneesh | AT5: Aneesh | AU5: =IF(AX5="","",IF(AX5=1,"Major",IF(AX5=3,"Critical",IF(AX5=0,"Minor","")))) -> Major | AV5: =K5&P5 -> 12825757Vijay Babu | AW5: =IF(U5="","",LEFT(U5,FIND("-",U5,1)-1)) -> Major | AX5: =IF(AW5="Minor",0,IF(AW5="Major",1,IF(AW5="Critical",3,""))) -> 1 | AY5: Trivandrum | AZ5: TRUE | BA5: =IF(U5="","",COUNTIF(U5,U5:U5)) -> 1 | BB5: =V5 -> 2 | BC5: Vijay Babu | BD5: mt_new | BE5: awaiting_upload | BF5: TRUE | BG5: =VLOOKUP(AM5,Group!$C:$H,5,0) -> AMC Group | BH5: =VLOOKUP(P5,others!$C:$G,5,0) -> MTX - India
A6: 46084.482 | B6: 46084.711 | C6: 46091.246 | D6: 46091.475 | E6: 46086.63 | F6: 46091.475 | G6: Devang Thakkar | H6: 2972 | I6: 6976.7833 | J6: cqa | K6: 12825757 | L6: William Smith, MD | M6: Adirondack Medical Center | N6: Clinic | O6: veejay_b@yahoo.com | P6: Vijay Babu | Q6: Trivandrum | R6: No Go | S6: 134.58 | T6: 98 | U6: Minor-Punctuation/Grammar/Feedback | V6: 2 | X6: Generic Operative Report | AA6: 360 | AB6: No | AC6: 600 | AD6: Normal | AE6: Achieved | AF6: 2 | AK6: =INT(D6) -> 46091 | AL6: ="Week"&WEEKNUM(D6) -> Week11 | AM6: AMC | AN6: =IF(AO6>98.5,"Go","NoGo") -> Go | AO6: =100-(AQ6/S6*100) -> 98.513895 | AP6: =IFERROR(AX6*V6,0) -> 0 | AQ6: =100-T6 -> 2 | AR6: Aneesh | AS6: Aneesh | AT6: Aneesh | AU6: =IF(AX6="","",IF(AX6=1,"Major",IF(AX6=3,"Critical",IF(AX6=0,"Minor","")))) -> Minor | AV6: =K6&P6 -> 12825757Vijay Babu | AW6: =IF(U6="","",LEFT(U6,FIND("-",U6,1)-1)) -> Minor | AX6: =IF(AW6="Minor",0,IF(AW6="Major",1,IF(AW6="Critical",3,""))) -> 0 | AY6: Trivandrum | AZ6: FALSE | BA6: =IF(U6="","",COUNTIF(U6,U6:U6)) -> 1 | BB6: =V6 -> 2 | BC6: Vijay Babu | BD6: mt_new | BE6: awaiting_upload | BF6: FALSE | BG6: =VLOOKUP(AM6,Group!$C:$H,5,0) -> AMC Group | BH6: =VLOOKUP(P6,others!$C:$G,5,0) -> MTX - India
A7: 46089.422 | B7: 46089.651 | C7: 46091.58 | D7: 46091.809 | E7: 46091.804 | F7: 46091.809 | G7: Vishal Mehta | H7: 456 | I7: 7.7167 | J7: cqa | K7: 12827216 | L7: Austin Christensen, MD | M7: Harmon Medical And Rehabilitation Hospital | N7: Clinic | O7: sandeepskn88@gmail.com | P7: Sandeep S | Q7: Trivandrum | R7: Go | S7: 75.85 | T7: 100 | V7: 0 | X7: Psychiatric Assessment | AA7: 1440 | AB7: No | AC7: 231 | AD7: Normal | AE7: Missed | AF7: 0 | AK7: =INT(D7) -> 46091 | AL7: ="Week"&WEEKNUM(D7) -> Week11 | AM7: HMRH | AN7: =IF(AO7>98.5,"Go","NoGo") -> Go | AO7: =100-(AQ7/S7*100) -> 100 | AP7: =IFERROR(AX7*V7,0) -> 0 | AQ7: =100-T7 -> 0 | AR7: Aneesh | AS7: Aneesh | AT7: Aneesh | AU7: =IF(AX7="","",IF(AX7=1,"Major",IF(AX7=3,"Critical",IF(AX7=0,"Minor","")))) | AV7: =K7&P7 -> 12827216Sandeep S | AW7: =IF(U7="","",LEFT(U7,FIND("-",U7,1)-1)) | AX7: =IF(AW7="Minor",0,IF(AW7="Major",1,IF(AW7="Critical",3,""))) | AY7: Trivandrum | AZ7: FALSE | BA7: =IF(U7="","",COUNTIF(U7,U7:U7)) | BB7: =V7 -> 0 | BC7: Sandeep S | BD7: mt_new | BE7: awaiting_upload | BF7: FALSE | BG7: =VLOOKUP(AM7,Group!$C:$H,5,0) -> Fundamental | BH7: =VLOOKUP(P7,others!$C:$G,5,0) -> MTX - India
A8: 46085.539 | B8: 46085.768 | C8: 46091.76 | D8: 46091.989 | E8: 46091.821 | F8: 46091.989 | G8: Devang Thakkar | H8: 822 | I8: 242.5333 | J8: cqa | K8: 12826205 | L8: John Decker, MD | M8: Adirondack Medical Center | N8: Clinic | O8: ushaaaam40@gmail.com | P8: Usha M | Q8: Trivandrum | R8: Go | S8: 24.6 | T8: 100 | U8: Minor-Punctuation/Grammar/Feedback | V8: 1 | X8: ENT Clinic History and Physical | AA8: 1440 | AB8: No | AC8: 193 | AD8: Normal | AE8: Achieved | AF8: 0 | AK8: =INT(D8) -> 46091 | AL8: ="Week"&WEEKNUM(D8) -> Week11 | AM8: AMC | AN8: =IF(AO8>98.5,"Go","NoGo") -> Go | AO8: =100-(AQ8/S8*100) -> 100 | AP8: =IFERROR(AX8*V8,0) -> 0 | AQ8: =100-T8 -> 0 | AR8: Aneesh | AS8: Aneesh | AT8: Aneesh | AU8: =IF(AX8="","",IF(AX8=1,"Major",IF(AX8=3,"Critical",IF(AX8=0,"Minor","")))) -> Minor | AV8: =K8&P8 -> 12826205Usha M | AW8: =IF(U8="","",LEFT(U8,FIND("-",U8,1)-1)) -> Minor | AX8: =IF(AW8="Minor",0,IF(AW8="Major",1,IF(AW8="Critical",3,""))) -> 0 | AY8: Trivandrum | AZ8: FALSE | BA8: =IF(U8="","",COUNTIF(U8,U8:U8)) -> 1 | BB8: =V8 -> 1 | BC8: Usha M | BD8: mt_new | BE8: awaiting_upload | BF8: FALSE | BG8: =VLOOKUP(AM8,Group!$C:$H,5,0) -> AMC Group | BH8: =VLOOKUP(P8,others!$C:$G,5,0) -> MTX - India
A9: 46087.618 | B9: 46087.847 | C9: 46091.764 | D9: 46091.993 | E9: 46091.507 | F9: 46091.993 | G9: Devang Thakkar | H9: 308 | I9: 699.25 | J9: cqa | K9: 12826941 | L9: John Decker, MD | M9: Adirondack Medical Center | N9: Clinic | O9: veejay_b@yahoo.com | P9: Vijay Babu | Q9: Trivandrum | R9: Go | S9: 38.66 | T9: 100 | V9: 0 | X9: ENT Clinic Follow-Up | AA9: 1440 | AB9: No | AC9: 367 | AD9: Normal | AE9: Achieved | AF9: 0 | AK9: =INT(D9) -> 46091 | AL9: ="Week"&WEEKNUM(D9) -> Week11 | AM9: AMC | AN9: =IF(AO9>98.5,"Go","NoGo") -> Go | AO9: =100-(AQ9/S9*100) -> 100 | AP9: =IFERROR(AX9*V9,0) -> 0 | AQ9: =100-T9 -> 0 | AR9: Aneesh | AS9: Aneesh | AT9: Aneesh | AU9: =IF(AX9="","",IF(AX9=1,"Major",IF(AX9=3,"Critical",IF(AX9=0,"Minor","")))) | AV9: =K9&P9 -> 12826941Vijay Babu | AW9: =IF(U9="","",LEFT(U9,FIND("-",U9,1)-1)) | AX9: =IF(AW9="Minor",0,IF(AW9="Major",1,IF(AW9="Critical",3,""))) | AY9: Trivandrum | AZ9: FALSE | BA9: =IF(U9="","",COUNTIF(U9,U9:U9)) | BB9: =V9 -> 0 | BC9: Vijay Babu | BD9: mt_new | BE9: awaiting_upload | BF9: FALSE | BG9: =VLOOKUP(AM9,Group!$C:$H,5,0) -> AMC Group | BH9: =VLOOKUP(P9,others!$C:$G,5,0) -> MTX - India
A10: 46087.622 | B10: 46087.852 | C10: 46091.767 | D10: 46091.996 | E10: 46091.508 | F10: 46091.996 | G10: Devang Thakkar | H10: 232 | I10: 703.2333 | J10: cqa | K10: 12826946 | L10: John Decker, MD | M10: Adirondack Medical Center | N10: Clinic | O10: veejay_b@yahoo.com | P10: Vijay Babu | Q10: Trivandrum | R10: Go | S10: 29.15 | T10: 100 | U10: Minor-Punctuation/Grammar/Feedback | V10: 2 | X10: ENT Clinic Follow-Up | AA10: 1440 | AB10: No | AC10: 259 | AD10: Normal | AE10: Achieved | AF10: 0 | AK10: =INT(D10) -> 46091 | AL10: ="Week"&WEEKNUM(D10) -> Week11 | AM10: AMC | AN10: =IF(AO10>98.5,"Go","NoGo") -> Go | AO10: =100-(AQ10/S10*100) -> 100 | AP10: =IFERROR(AX10*V10,0) -> 0 | AQ10: =100-T10 -> 0 | AR10: Aneesh | AS10: Aneesh | AT10: Aneesh | AU10: =IF(AX10="","",IF(AX10=1,"Major",IF(AX10=3,"Critical",IF(AX10=0,"Minor","")))) -> Minor | AV10: =K10&P10 -> 12826946Vijay Babu | AW10: =IF(U10="","",LEFT(U10,FIND("-",U10,1)-1)) -> Minor | AX10: =IF(AW10="Minor",0,IF(AW10="Major",1,IF(AW10="Critical",3,""))) -> 0 | AY10: Trivandrum | AZ10: FALSE | BA10: =IF(U10="","",COUNTIF(U10,U10:U10)) -> 1 | BB10: =V10 -> 2 | BC10: Vijay Babu | BD10: mt_new | BE10: awaiting_upload | BF10: FALSE | BG10: =VLOOKUP(AM10,Group!$C:$H,5,0) -> AMC Group | BH10: =VLOOKUP(P10,others!$C:$G,5,0) -> MTX - India
A11: 46087.553 | B11: 46087.782 | C11: 46091.776 | D11: 46092.005 | E11: 46092 | F11: 46092.005 | G11: Devang Thakkar | H11: 413 | I11: 6.9667 | J11: cqa | K11: 12826909 | L11: John Decker, MD | M11: Adirondack Medical Center | N11: Clinic | O11: veejay_b@yahoo.com | P11: Vijay Babu | Q11: Trivandrum | R11: Go | S11: 3.51 | T11: 100 | V11: 0 | X11: ENT Clinic Follow-Up | AA11: 1440 | AB11: No | AC11: 40 | AD11: Normal | AE11: Achieved | AF11: 0 | AK11: =INT(D11) -> 46092 | AL11: ="Week"&WEEKNUM(D11) -> Week11 | AM11: AMC | AN11: =IF(AO11>98.5,"Go","NoGo") -> Go | AO11: =100-(AQ11/S11*100) -> 100 | AP11: =IFERROR(AX11*V11,0) -> 0 | AQ11: =100-T11 -> 0 | AR11: Aneesh | AS11: Aneesh | AT11: Aneesh | AU11: =IF(AX11="","",IF(AX11=1,"Major",IF(AX11=3,"Critical",IF(AX11=0,"Minor","")))) | AV11: =K11&P11 -> 12826909Vijay Babu | AW11: =IF(U11="","",LEFT(U11,FIND("-",U11,1)-1)) | AX11: =IF(AW11="Minor",0,IF(AW11="Major",1,IF(AW11="Critical",3,""))) | AY11: Trivandrum | AZ11: FALSE | BA11: =IF(U11="","",COUNTIF(U11,U11:U11)) | BB11: =V11 -> 0 | BC11: Vijay Babu | BD11: mt_new | BE11: awaiting_upload | BF11: FALSE | BG11: =VLOOKUP(AM11,Group!$C:$H,5,0) -> AMC Group | BH11: =VLOOKUP(P11,others!$C:$G,5,0) -> MTX - India
